{
 "cells": [
  {
   "cell_type": "code",
   "execution_count": 8,
   "metadata": {},
   "outputs": [
    {
     "name": "stdout",
     "output_type": "stream",
     "text": [
      "{\"detail\":\"Could not validate credentials\"}"
     ]
    }
   ],
   "source": [
    "import requests\n",
    "\n",
    "headers = {\n",
    "    \"accept\": \"application/json\",\n",
    "    \"Authorization\": \"Bearer eyJhbGciOiJIUzI1NiIsInR5cCI6IkpXVCJ9.eyJleHAiOjE2OTQxNjU2NTgsInN1YiI6IjEwNiJ9.yIPEGFSn5NHCKKX_gln-zVa7TJwv3XekM5-hMzRpMZs\",\n",
    "    \"Content-Type\": \"application/x-www-form-urlencoded\",\n",
    "}\n",
    "\n",
    "params = {\n",
    "    \"query\": \"what is allowed by this document\",\n",
    "    \"document_id\": \"87\",\n",
    "}\n",
    "\n",
    "with requests.post(\n",
    "    \"http://localhost:8000/api/v1/documents/query-stream\",\n",
    "    params=params,\n",
    "    headers=headers,\n",
    "    stream=True,\n",
    ") as r:\n",
    "    for chunk in r.iter_lines(None, decode_unicode=True):\n",
    "        if chunk:\n",
    "            print(chunk, end=\"\", flush=True)\n"
   ]
  },
  {
   "cell_type": "code",
   "execution_count": 19,
   "metadata": {},
   "outputs": [
    {
     "ename": "ConnectError",
     "evalue": "[Errno 111] Connection refused",
     "output_type": "error",
     "traceback": [
      "\u001b[0;31m---------------------------------------------------------------------------\u001b[0m",
      "\u001b[0;31mConnectionRefusedError\u001b[0m                    Traceback (most recent call last)",
      "File \u001b[0;32m~/.local/lib/python3.10/site-packages/httpcore/_exceptions.py:10\u001b[0m, in \u001b[0;36mmap_exceptions\u001b[0;34m(map)\u001b[0m\n\u001b[1;32m      9\u001b[0m \u001b[39mtry\u001b[39;00m:\n\u001b[0;32m---> 10\u001b[0m     \u001b[39myield\u001b[39;00m\n\u001b[1;32m     11\u001b[0m \u001b[39mexcept\u001b[39;00m \u001b[39mException\u001b[39;00m \u001b[39mas\u001b[39;00m exc:  \u001b[39m# noqa: PIE786\u001b[39;00m\n",
      "File \u001b[0;32m~/.local/lib/python3.10/site-packages/httpcore/backends/sync.py:94\u001b[0m, in \u001b[0;36mSyncBackend.connect_tcp\u001b[0;34m(self, host, port, timeout, local_address)\u001b[0m\n\u001b[1;32m     93\u001b[0m \u001b[39mwith\u001b[39;00m map_exceptions(exc_map):\n\u001b[0;32m---> 94\u001b[0m     sock \u001b[39m=\u001b[39m socket\u001b[39m.\u001b[39;49mcreate_connection(\n\u001b[1;32m     95\u001b[0m         address, timeout, source_address\u001b[39m=\u001b[39;49msource_address\n\u001b[1;32m     96\u001b[0m     )\n\u001b[1;32m     97\u001b[0m \u001b[39mreturn\u001b[39;00m SyncStream(sock)\n",
      "File \u001b[0;32m/usr/lib/python3.10/socket.py:845\u001b[0m, in \u001b[0;36mcreate_connection\u001b[0;34m(address, timeout, source_address)\u001b[0m\n\u001b[1;32m    844\u001b[0m \u001b[39mtry\u001b[39;00m:\n\u001b[0;32m--> 845\u001b[0m     \u001b[39mraise\u001b[39;00m err\n\u001b[1;32m    846\u001b[0m \u001b[39mfinally\u001b[39;00m:\n\u001b[1;32m    847\u001b[0m     \u001b[39m# Break explicitly a reference cycle\u001b[39;00m\n",
      "File \u001b[0;32m/usr/lib/python3.10/socket.py:833\u001b[0m, in \u001b[0;36mcreate_connection\u001b[0;34m(address, timeout, source_address)\u001b[0m\n\u001b[1;32m    832\u001b[0m     sock\u001b[39m.\u001b[39mbind(source_address)\n\u001b[0;32m--> 833\u001b[0m sock\u001b[39m.\u001b[39;49mconnect(sa)\n\u001b[1;32m    834\u001b[0m \u001b[39m# Break explicitly a reference cycle\u001b[39;00m\n",
      "\u001b[0;31mConnectionRefusedError\u001b[0m: [Errno 111] Connection refused",
      "\nDuring handling of the above exception, another exception occurred:\n",
      "\u001b[0;31mConnectError\u001b[0m                              Traceback (most recent call last)",
      "File \u001b[0;32m~/.local/lib/python3.10/site-packages/httpx/_transports/default.py:60\u001b[0m, in \u001b[0;36mmap_httpcore_exceptions\u001b[0;34m()\u001b[0m\n\u001b[1;32m     59\u001b[0m \u001b[39mtry\u001b[39;00m:\n\u001b[0;32m---> 60\u001b[0m     \u001b[39myield\u001b[39;00m\n\u001b[1;32m     61\u001b[0m \u001b[39mexcept\u001b[39;00m \u001b[39mException\u001b[39;00m \u001b[39mas\u001b[39;00m exc:  \u001b[39m# noqa: PIE-786\u001b[39;00m\n",
      "File \u001b[0;32m~/.local/lib/python3.10/site-packages/httpx/_transports/default.py:218\u001b[0m, in \u001b[0;36mHTTPTransport.handle_request\u001b[0;34m(self, request)\u001b[0m\n\u001b[1;32m    217\u001b[0m \u001b[39mwith\u001b[39;00m map_httpcore_exceptions():\n\u001b[0;32m--> 218\u001b[0m     resp \u001b[39m=\u001b[39m \u001b[39mself\u001b[39;49m\u001b[39m.\u001b[39;49m_pool\u001b[39m.\u001b[39;49mhandle_request(req)\n\u001b[1;32m    220\u001b[0m \u001b[39massert\u001b[39;00m \u001b[39misinstance\u001b[39m(resp\u001b[39m.\u001b[39mstream, typing\u001b[39m.\u001b[39mIterable)\n",
      "File \u001b[0;32m~/.local/lib/python3.10/site-packages/httpcore/_sync/connection_pool.py:253\u001b[0m, in \u001b[0;36mConnectionPool.handle_request\u001b[0;34m(self, request)\u001b[0m\n\u001b[1;32m    252\u001b[0m     \u001b[39mself\u001b[39m\u001b[39m.\u001b[39mresponse_closed(status)\n\u001b[0;32m--> 253\u001b[0m     \u001b[39mraise\u001b[39;00m exc\n\u001b[1;32m    254\u001b[0m \u001b[39melse\u001b[39;00m:\n",
      "File \u001b[0;32m~/.local/lib/python3.10/site-packages/httpcore/_sync/connection_pool.py:237\u001b[0m, in \u001b[0;36mConnectionPool.handle_request\u001b[0;34m(self, request)\u001b[0m\n\u001b[1;32m    236\u001b[0m \u001b[39mtry\u001b[39;00m:\n\u001b[0;32m--> 237\u001b[0m     response \u001b[39m=\u001b[39m connection\u001b[39m.\u001b[39;49mhandle_request(request)\n\u001b[1;32m    238\u001b[0m \u001b[39mexcept\u001b[39;00m ConnectionNotAvailable:\n\u001b[1;32m    239\u001b[0m     \u001b[39m# The ConnectionNotAvailable exception is a special case, that\u001b[39;00m\n\u001b[1;32m    240\u001b[0m     \u001b[39m# indicates we need to retry the request on a new connection.\u001b[39;00m\n\u001b[0;32m   (...)\u001b[0m\n\u001b[1;32m    244\u001b[0m     \u001b[39m# might end up as an HTTP/2 connection, but which actually ends\u001b[39;00m\n\u001b[1;32m    245\u001b[0m     \u001b[39m# up as HTTP/1.1.\u001b[39;00m\n",
      "File \u001b[0;32m~/.local/lib/python3.10/site-packages/httpcore/_sync/connection.py:86\u001b[0m, in \u001b[0;36mHTTPConnection.handle_request\u001b[0;34m(self, request)\u001b[0m\n\u001b[1;32m     85\u001b[0m         \u001b[39mself\u001b[39m\u001b[39m.\u001b[39m_connect_failed \u001b[39m=\u001b[39m \u001b[39mTrue\u001b[39;00m\n\u001b[0;32m---> 86\u001b[0m         \u001b[39mraise\u001b[39;00m exc\n\u001b[1;32m     87\u001b[0m \u001b[39melif\u001b[39;00m \u001b[39mnot\u001b[39;00m \u001b[39mself\u001b[39m\u001b[39m.\u001b[39m_connection\u001b[39m.\u001b[39mis_available():\n",
      "File \u001b[0;32m~/.local/lib/python3.10/site-packages/httpcore/_sync/connection.py:63\u001b[0m, in \u001b[0;36mHTTPConnection.handle_request\u001b[0;34m(self, request)\u001b[0m\n\u001b[1;32m     62\u001b[0m \u001b[39mtry\u001b[39;00m:\n\u001b[0;32m---> 63\u001b[0m     stream \u001b[39m=\u001b[39m \u001b[39mself\u001b[39;49m\u001b[39m.\u001b[39;49m_connect(request)\n\u001b[1;32m     65\u001b[0m     ssl_object \u001b[39m=\u001b[39m stream\u001b[39m.\u001b[39mget_extra_info(\u001b[39m\"\u001b[39m\u001b[39mssl_object\u001b[39m\u001b[39m\"\u001b[39m)\n",
      "File \u001b[0;32m~/.local/lib/python3.10/site-packages/httpcore/_sync/connection.py:111\u001b[0m, in \u001b[0;36mHTTPConnection._connect\u001b[0;34m(self, request)\u001b[0m\n\u001b[1;32m    108\u001b[0m \u001b[39mwith\u001b[39;00m Trace(\n\u001b[1;32m    109\u001b[0m     \u001b[39m\"\u001b[39m\u001b[39mconnection.connect_tcp\u001b[39m\u001b[39m\"\u001b[39m, request, kwargs\n\u001b[1;32m    110\u001b[0m ) \u001b[39mas\u001b[39;00m trace:\n\u001b[0;32m--> 111\u001b[0m     stream \u001b[39m=\u001b[39m \u001b[39mself\u001b[39;49m\u001b[39m.\u001b[39;49m_network_backend\u001b[39m.\u001b[39;49mconnect_tcp(\u001b[39m*\u001b[39;49m\u001b[39m*\u001b[39;49mkwargs)\n\u001b[1;32m    112\u001b[0m     trace\u001b[39m.\u001b[39mreturn_value \u001b[39m=\u001b[39m stream\n",
      "File \u001b[0;32m~/.local/lib/python3.10/site-packages/httpcore/backends/sync.py:93\u001b[0m, in \u001b[0;36mSyncBackend.connect_tcp\u001b[0;34m(self, host, port, timeout, local_address)\u001b[0m\n\u001b[1;32m     89\u001b[0m exc_map: ExceptionMapping \u001b[39m=\u001b[39m {\n\u001b[1;32m     90\u001b[0m     socket\u001b[39m.\u001b[39mtimeout: ConnectTimeout,\n\u001b[1;32m     91\u001b[0m     \u001b[39mOSError\u001b[39;00m: ConnectError,\n\u001b[1;32m     92\u001b[0m }\n\u001b[0;32m---> 93\u001b[0m \u001b[39mwith\u001b[39;00m map_exceptions(exc_map):\n\u001b[1;32m     94\u001b[0m     sock \u001b[39m=\u001b[39m socket\u001b[39m.\u001b[39mcreate_connection(\n\u001b[1;32m     95\u001b[0m         address, timeout, source_address\u001b[39m=\u001b[39msource_address\n\u001b[1;32m     96\u001b[0m     )\n",
      "File \u001b[0;32m/usr/lib/python3.10/contextlib.py:153\u001b[0m, in \u001b[0;36m_GeneratorContextManager.__exit__\u001b[0;34m(self, typ, value, traceback)\u001b[0m\n\u001b[1;32m    152\u001b[0m \u001b[39mtry\u001b[39;00m:\n\u001b[0;32m--> 153\u001b[0m     \u001b[39mself\u001b[39;49m\u001b[39m.\u001b[39;49mgen\u001b[39m.\u001b[39;49mthrow(typ, value, traceback)\n\u001b[1;32m    154\u001b[0m \u001b[39mexcept\u001b[39;00m \u001b[39mStopIteration\u001b[39;00m \u001b[39mas\u001b[39;00m exc:\n\u001b[1;32m    155\u001b[0m     \u001b[39m# Suppress StopIteration *unless* it's the same exception that\u001b[39;00m\n\u001b[1;32m    156\u001b[0m     \u001b[39m# was passed to throw().  This prevents a StopIteration\u001b[39;00m\n\u001b[1;32m    157\u001b[0m     \u001b[39m# raised inside the \"with\" statement from being suppressed.\u001b[39;00m\n",
      "File \u001b[0;32m~/.local/lib/python3.10/site-packages/httpcore/_exceptions.py:14\u001b[0m, in \u001b[0;36mmap_exceptions\u001b[0;34m(map)\u001b[0m\n\u001b[1;32m     13\u001b[0m     \u001b[39mif\u001b[39;00m \u001b[39misinstance\u001b[39m(exc, from_exc):\n\u001b[0;32m---> 14\u001b[0m         \u001b[39mraise\u001b[39;00m to_exc(exc)\n\u001b[1;32m     15\u001b[0m \u001b[39mraise\u001b[39;00m\n",
      "\u001b[0;31mConnectError\u001b[0m: [Errno 111] Connection refused",
      "\nThe above exception was the direct cause of the following exception:\n",
      "\u001b[0;31mConnectError\u001b[0m                              Traceback (most recent call last)",
      "Cell \u001b[0;32mIn[19], line 12\u001b[0m\n\u001b[1;32m     10\u001b[0m \u001b[39mwith\u001b[39;00m httpx\u001b[39m.\u001b[39mClient(timeout\u001b[39m=\u001b[39m\u001b[39m200.0\u001b[39m) \u001b[39mas\u001b[39;00m client:\n\u001b[1;32m     11\u001b[0m     start \u001b[39m=\u001b[39m time\u001b[39m.\u001b[39mtime()\n\u001b[0;32m---> 12\u001b[0m     r \u001b[39m=\u001b[39m client\u001b[39m.\u001b[39;49mpost(url, data\u001b[39m=\u001b[39;49mdata, files\u001b[39m=\u001b[39;49mfiles, headers\u001b[39m=\u001b[39;49mheaders)\n\u001b[1;32m     13\u001b[0m     end \u001b[39m=\u001b[39m time\u001b[39m.\u001b[39mtime()\n\u001b[1;32m     14\u001b[0m     \u001b[39mprint\u001b[39m(\u001b[39mf\u001b[39m\u001b[39m'\u001b[39m\u001b[39mTime elapsed: \u001b[39m\u001b[39m{\u001b[39;00mend\u001b[39m \u001b[39m\u001b[39m-\u001b[39m\u001b[39m \u001b[39mstart\u001b[39m}\u001b[39;00m\u001b[39ms\u001b[39m\u001b[39m'\u001b[39m)\n",
      "File \u001b[0;32m~/.local/lib/python3.10/site-packages/httpx/_client.py:1136\u001b[0m, in \u001b[0;36mClient.post\u001b[0;34m(self, url, content, data, files, json, params, headers, cookies, auth, follow_redirects, timeout, extensions)\u001b[0m\n\u001b[1;32m   1115\u001b[0m \u001b[39mdef\u001b[39;00m \u001b[39mpost\u001b[39m(\n\u001b[1;32m   1116\u001b[0m     \u001b[39mself\u001b[39m,\n\u001b[1;32m   1117\u001b[0m     url: URLTypes,\n\u001b[0;32m   (...)\u001b[0m\n\u001b[1;32m   1129\u001b[0m     extensions: typing\u001b[39m.\u001b[39mOptional[RequestExtensions] \u001b[39m=\u001b[39m \u001b[39mNone\u001b[39;00m,\n\u001b[1;32m   1130\u001b[0m ) \u001b[39m-\u001b[39m\u001b[39m>\u001b[39m Response:\n\u001b[1;32m   1131\u001b[0m \u001b[39m    \u001b[39m\u001b[39m\"\"\"\u001b[39;00m\n\u001b[1;32m   1132\u001b[0m \u001b[39m    Send a `POST` request.\u001b[39;00m\n\u001b[1;32m   1133\u001b[0m \n\u001b[1;32m   1134\u001b[0m \u001b[39m    **Parameters**: See `httpx.request`.\u001b[39;00m\n\u001b[1;32m   1135\u001b[0m \u001b[39m    \"\"\"\u001b[39;00m\n\u001b[0;32m-> 1136\u001b[0m     \u001b[39mreturn\u001b[39;00m \u001b[39mself\u001b[39;49m\u001b[39m.\u001b[39;49mrequest(\n\u001b[1;32m   1137\u001b[0m         \u001b[39m\"\u001b[39;49m\u001b[39mPOST\u001b[39;49m\u001b[39m\"\u001b[39;49m,\n\u001b[1;32m   1138\u001b[0m         url,\n\u001b[1;32m   1139\u001b[0m         content\u001b[39m=\u001b[39;49mcontent,\n\u001b[1;32m   1140\u001b[0m         data\u001b[39m=\u001b[39;49mdata,\n\u001b[1;32m   1141\u001b[0m         files\u001b[39m=\u001b[39;49mfiles,\n\u001b[1;32m   1142\u001b[0m         json\u001b[39m=\u001b[39;49mjson,\n\u001b[1;32m   1143\u001b[0m         params\u001b[39m=\u001b[39;49mparams,\n\u001b[1;32m   1144\u001b[0m         headers\u001b[39m=\u001b[39;49mheaders,\n\u001b[1;32m   1145\u001b[0m         cookies\u001b[39m=\u001b[39;49mcookies,\n\u001b[1;32m   1146\u001b[0m         auth\u001b[39m=\u001b[39;49mauth,\n\u001b[1;32m   1147\u001b[0m         follow_redirects\u001b[39m=\u001b[39;49mfollow_redirects,\n\u001b[1;32m   1148\u001b[0m         timeout\u001b[39m=\u001b[39;49mtimeout,\n\u001b[1;32m   1149\u001b[0m         extensions\u001b[39m=\u001b[39;49mextensions,\n\u001b[1;32m   1150\u001b[0m     )\n",
      "File \u001b[0;32m~/.local/lib/python3.10/site-packages/httpx/_client.py:821\u001b[0m, in \u001b[0;36mClient.request\u001b[0;34m(self, method, url, content, data, files, json, params, headers, cookies, auth, follow_redirects, timeout, extensions)\u001b[0m\n\u001b[1;32m    806\u001b[0m     warnings\u001b[39m.\u001b[39mwarn(message, \u001b[39mDeprecationWarning\u001b[39;00m)\n\u001b[1;32m    808\u001b[0m request \u001b[39m=\u001b[39m \u001b[39mself\u001b[39m\u001b[39m.\u001b[39mbuild_request(\n\u001b[1;32m    809\u001b[0m     method\u001b[39m=\u001b[39mmethod,\n\u001b[1;32m    810\u001b[0m     url\u001b[39m=\u001b[39murl,\n\u001b[0;32m   (...)\u001b[0m\n\u001b[1;32m    819\u001b[0m     extensions\u001b[39m=\u001b[39mextensions,\n\u001b[1;32m    820\u001b[0m )\n\u001b[0;32m--> 821\u001b[0m \u001b[39mreturn\u001b[39;00m \u001b[39mself\u001b[39;49m\u001b[39m.\u001b[39;49msend(request, auth\u001b[39m=\u001b[39;49mauth, follow_redirects\u001b[39m=\u001b[39;49mfollow_redirects)\n",
      "File \u001b[0;32m~/.local/lib/python3.10/site-packages/httpx/_client.py:908\u001b[0m, in \u001b[0;36mClient.send\u001b[0;34m(self, request, stream, auth, follow_redirects)\u001b[0m\n\u001b[1;32m    900\u001b[0m follow_redirects \u001b[39m=\u001b[39m (\n\u001b[1;32m    901\u001b[0m     \u001b[39mself\u001b[39m\u001b[39m.\u001b[39mfollow_redirects\n\u001b[1;32m    902\u001b[0m     \u001b[39mif\u001b[39;00m \u001b[39misinstance\u001b[39m(follow_redirects, UseClientDefault)\n\u001b[1;32m    903\u001b[0m     \u001b[39melse\u001b[39;00m follow_redirects\n\u001b[1;32m    904\u001b[0m )\n\u001b[1;32m    906\u001b[0m auth \u001b[39m=\u001b[39m \u001b[39mself\u001b[39m\u001b[39m.\u001b[39m_build_request_auth(request, auth)\n\u001b[0;32m--> 908\u001b[0m response \u001b[39m=\u001b[39m \u001b[39mself\u001b[39;49m\u001b[39m.\u001b[39;49m_send_handling_auth(\n\u001b[1;32m    909\u001b[0m     request,\n\u001b[1;32m    910\u001b[0m     auth\u001b[39m=\u001b[39;49mauth,\n\u001b[1;32m    911\u001b[0m     follow_redirects\u001b[39m=\u001b[39;49mfollow_redirects,\n\u001b[1;32m    912\u001b[0m     history\u001b[39m=\u001b[39;49m[],\n\u001b[1;32m    913\u001b[0m )\n\u001b[1;32m    914\u001b[0m \u001b[39mtry\u001b[39;00m:\n\u001b[1;32m    915\u001b[0m     \u001b[39mif\u001b[39;00m \u001b[39mnot\u001b[39;00m stream:\n",
      "File \u001b[0;32m~/.local/lib/python3.10/site-packages/httpx/_client.py:936\u001b[0m, in \u001b[0;36mClient._send_handling_auth\u001b[0;34m(self, request, auth, follow_redirects, history)\u001b[0m\n\u001b[1;32m    933\u001b[0m request \u001b[39m=\u001b[39m \u001b[39mnext\u001b[39m(auth_flow)\n\u001b[1;32m    935\u001b[0m \u001b[39mwhile\u001b[39;00m \u001b[39mTrue\u001b[39;00m:\n\u001b[0;32m--> 936\u001b[0m     response \u001b[39m=\u001b[39m \u001b[39mself\u001b[39;49m\u001b[39m.\u001b[39;49m_send_handling_redirects(\n\u001b[1;32m    937\u001b[0m         request,\n\u001b[1;32m    938\u001b[0m         follow_redirects\u001b[39m=\u001b[39;49mfollow_redirects,\n\u001b[1;32m    939\u001b[0m         history\u001b[39m=\u001b[39;49mhistory,\n\u001b[1;32m    940\u001b[0m     )\n\u001b[1;32m    941\u001b[0m     \u001b[39mtry\u001b[39;00m:\n\u001b[1;32m    942\u001b[0m         \u001b[39mtry\u001b[39;00m:\n",
      "File \u001b[0;32m~/.local/lib/python3.10/site-packages/httpx/_client.py:973\u001b[0m, in \u001b[0;36mClient._send_handling_redirects\u001b[0;34m(self, request, follow_redirects, history)\u001b[0m\n\u001b[1;32m    970\u001b[0m \u001b[39mfor\u001b[39;00m hook \u001b[39min\u001b[39;00m \u001b[39mself\u001b[39m\u001b[39m.\u001b[39m_event_hooks[\u001b[39m\"\u001b[39m\u001b[39mrequest\u001b[39m\u001b[39m\"\u001b[39m]:\n\u001b[1;32m    971\u001b[0m     hook(request)\n\u001b[0;32m--> 973\u001b[0m response \u001b[39m=\u001b[39m \u001b[39mself\u001b[39;49m\u001b[39m.\u001b[39;49m_send_single_request(request)\n\u001b[1;32m    974\u001b[0m \u001b[39mtry\u001b[39;00m:\n\u001b[1;32m    975\u001b[0m     \u001b[39mfor\u001b[39;00m hook \u001b[39min\u001b[39;00m \u001b[39mself\u001b[39m\u001b[39m.\u001b[39m_event_hooks[\u001b[39m\"\u001b[39m\u001b[39mresponse\u001b[39m\u001b[39m\"\u001b[39m]:\n",
      "File \u001b[0;32m~/.local/lib/python3.10/site-packages/httpx/_client.py:1009\u001b[0m, in \u001b[0;36mClient._send_single_request\u001b[0;34m(self, request)\u001b[0m\n\u001b[1;32m   1004\u001b[0m     \u001b[39mraise\u001b[39;00m \u001b[39mRuntimeError\u001b[39;00m(\n\u001b[1;32m   1005\u001b[0m         \u001b[39m\"\u001b[39m\u001b[39mAttempted to send an async request with a sync Client instance.\u001b[39m\u001b[39m\"\u001b[39m\n\u001b[1;32m   1006\u001b[0m     )\n\u001b[1;32m   1008\u001b[0m \u001b[39mwith\u001b[39;00m request_context(request\u001b[39m=\u001b[39mrequest):\n\u001b[0;32m-> 1009\u001b[0m     response \u001b[39m=\u001b[39m transport\u001b[39m.\u001b[39;49mhandle_request(request)\n\u001b[1;32m   1011\u001b[0m \u001b[39massert\u001b[39;00m \u001b[39misinstance\u001b[39m(response\u001b[39m.\u001b[39mstream, SyncByteStream)\n\u001b[1;32m   1013\u001b[0m response\u001b[39m.\u001b[39mrequest \u001b[39m=\u001b[39m request\n",
      "File \u001b[0;32m~/.local/lib/python3.10/site-packages/httpx/_transports/default.py:217\u001b[0m, in \u001b[0;36mHTTPTransport.handle_request\u001b[0;34m(self, request)\u001b[0m\n\u001b[1;32m    203\u001b[0m \u001b[39massert\u001b[39;00m \u001b[39misinstance\u001b[39m(request\u001b[39m.\u001b[39mstream, SyncByteStream)\n\u001b[1;32m    205\u001b[0m req \u001b[39m=\u001b[39m httpcore\u001b[39m.\u001b[39mRequest(\n\u001b[1;32m    206\u001b[0m     method\u001b[39m=\u001b[39mrequest\u001b[39m.\u001b[39mmethod,\n\u001b[1;32m    207\u001b[0m     url\u001b[39m=\u001b[39mhttpcore\u001b[39m.\u001b[39mURL(\n\u001b[0;32m   (...)\u001b[0m\n\u001b[1;32m    215\u001b[0m     extensions\u001b[39m=\u001b[39mrequest\u001b[39m.\u001b[39mextensions,\n\u001b[1;32m    216\u001b[0m )\n\u001b[0;32m--> 217\u001b[0m \u001b[39mwith\u001b[39;00m map_httpcore_exceptions():\n\u001b[1;32m    218\u001b[0m     resp \u001b[39m=\u001b[39m \u001b[39mself\u001b[39m\u001b[39m.\u001b[39m_pool\u001b[39m.\u001b[39mhandle_request(req)\n\u001b[1;32m    220\u001b[0m \u001b[39massert\u001b[39;00m \u001b[39misinstance\u001b[39m(resp\u001b[39m.\u001b[39mstream, typing\u001b[39m.\u001b[39mIterable)\n",
      "File \u001b[0;32m/usr/lib/python3.10/contextlib.py:153\u001b[0m, in \u001b[0;36m_GeneratorContextManager.__exit__\u001b[0;34m(self, typ, value, traceback)\u001b[0m\n\u001b[1;32m    151\u001b[0m     value \u001b[39m=\u001b[39m typ()\n\u001b[1;32m    152\u001b[0m \u001b[39mtry\u001b[39;00m:\n\u001b[0;32m--> 153\u001b[0m     \u001b[39mself\u001b[39;49m\u001b[39m.\u001b[39;49mgen\u001b[39m.\u001b[39;49mthrow(typ, value, traceback)\n\u001b[1;32m    154\u001b[0m \u001b[39mexcept\u001b[39;00m \u001b[39mStopIteration\u001b[39;00m \u001b[39mas\u001b[39;00m exc:\n\u001b[1;32m    155\u001b[0m     \u001b[39m# Suppress StopIteration *unless* it's the same exception that\u001b[39;00m\n\u001b[1;32m    156\u001b[0m     \u001b[39m# was passed to throw().  This prevents a StopIteration\u001b[39;00m\n\u001b[1;32m    157\u001b[0m     \u001b[39m# raised inside the \"with\" statement from being suppressed.\u001b[39;00m\n\u001b[1;32m    158\u001b[0m     \u001b[39mreturn\u001b[39;00m exc \u001b[39mis\u001b[39;00m \u001b[39mnot\u001b[39;00m value\n",
      "File \u001b[0;32m~/.local/lib/python3.10/site-packages/httpx/_transports/default.py:77\u001b[0m, in \u001b[0;36mmap_httpcore_exceptions\u001b[0;34m()\u001b[0m\n\u001b[1;32m     74\u001b[0m     \u001b[39mraise\u001b[39;00m\n\u001b[1;32m     76\u001b[0m message \u001b[39m=\u001b[39m \u001b[39mstr\u001b[39m(exc)\n\u001b[0;32m---> 77\u001b[0m \u001b[39mraise\u001b[39;00m mapped_exc(message) \u001b[39mfrom\u001b[39;00m \u001b[39mexc\u001b[39;00m\n",
      "\u001b[0;31mConnectError\u001b[0m: [Errno 111] Connection refused"
     ]
    }
   ],
   "source": [
    "import httpx\n",
    "import time\n",
    "\n",
    "url ='http://localhost:8000/api/v1/documents/upsert-stream'\n",
    "files = {'file': open('/home/boumaza/Downloads/scrumprimer20.pdf', 'rb')}\n",
    "headers={\"Authorization\": \"Bearer eyJhbGciOiJIUzI1NiIsInR5cCI6IkpXVCJ9.eyJleHAiOjE2OTcwODcwMDYsInN1YiI6IjQifQ._qPTbb98euik7wOA3Kz49s3G4suhwcQ3pXnGs5gHnOM\",\n",
    "         'Filename': 'scrumprimer20.pdf'}\n",
    "data = {'data': 'Hello World!'}\n",
    "\n",
    "with httpx.Client(timeout=200.0) as client:\n",
    "    start = time.time()\n",
    "    r = client.post(url, data=data, files=files, headers=headers)\n",
    "    end = time.time()\n",
    "    print(f'Time elapsed: {end - start}s')\n",
    "    print(r.status_code, r.json(), sep=' ')"
   ]
  }
 ],
 "metadata": {
  "kernelspec": {
   "display_name": "Python 3 (ipykernel)",
   "language": "python",
   "name": "python3"
  },
  "language_info": {
   "codemirror_mode": {
    "name": "ipython",
    "version": 3
   },
   "file_extension": ".py",
   "mimetype": "text/x-python",
   "name": "python",
   "nbconvert_exporter": "python",
   "pygments_lexer": "ipython3",
   "version": "3.10.12"
  }
 },
 "nbformat": 4,
 "nbformat_minor": 4
}
